<mujoco model="robotiq_arg85_description">
  <compiler angle="radian"/>

  <asset>
    <mesh name="robotiq_85_base_link_coarse" file="robotiq_85_base_link_coarse.STL"/>
    <mesh name="outer_knuckle_coarse" file="outer_knuckle_coarse.STL"/>
    <mesh name="outer_finger_coarse" file="outer_finger_coarse.STL"/>
    <mesh name="inner_knuckle_coarse" file="inner_knuckle_coarse.STL"/>
    <mesh name="inner_finger_coarse" file="inner_finger_coarse.STL"/>
  </asset>

  <worldbody>
    <body name="robotiq_85_base_link">
      <inertial pos="0.00021987 -2.3546e-10 0.030163" quat="0.707058 0.00723369 0.00723345 0.707081" mass="0.30915" diaginertia="0.00030737 0.000289758 0.000199102"/>
      <joint name="floating joint" type="free" limited="false" actuatorfrclimited="false"/>
      <geom type="mesh" rgba="0.1 0.1 0.1 1" mesh="robotiq_85_base_link_coarse"/>
      <body name="left_outer_knuckle" pos="0.0306011 0 0.062792">
        <inertial pos="0.0299636 7.39879e-12 0.0161054" quat="0.704933 0.0554073 0.0554073 0.704933" mass="0.0341578" diaginertia="1.12323e-05 1.05984e-05 4.63087e-06"/>
        <joint name="finger_joint" pos="0 0 0" axis="0 -1 0" range="0 0.725" actuatorfrcrange="-1000 1000"/>
        <geom type="mesh" rgba="0.1 0.1 0.1 1" mesh="outer_knuckle_coarse"/>
        <geom pos="0.031691 0 -0.00193396" type="mesh" rgba="0.1 0.1 0.1 1" mesh="outer_finger_coarse"/>
      </body>
      <body name="left_inner_knuckle" pos="0.0127 0 0.0693075">
        <inertial pos="0.0170975 -3.93809e-10 0.0224918" quat="0.947655 0 -0.319297 0" mass="0.0110931" diaginertia="5.59353e-06 3.96549e-06 1.88108e-06"/>
        <joint name="left_inner_knuckle_joint" pos="0 0 0" axis="0 -1 0" range="0 0.8757" actuatorfrcrange="-1000 1000"/>
        <geom type="mesh" rgba="0.1 0.1 0.1 1" mesh="inner_knuckle_coarse"/>
        <body name="left_inner_finger" pos="0.0345853 0 0.045497">
          <inertial pos="0.00602756 0 0.00669926" quat="0.699065 0.106339 0.106339 0.699065" mass="0.00724255" diaginertia="1.70064e-06 1.58577e-06 3.69621e-07"/>
          <joint name="left_inner_finger_joint" pos="0 0 0" axis="0 -1 0" range="0 0.8757" actuatorfrcrange="-1000 1000"/>
          <geom type="mesh" rgba="0.1 0.1 0.1 1" mesh="inner_finger_coarse"/>
        </body>
      </body>
      <body name="right_inner_knuckle" pos="-0.0127 0 0.0693075" quat="0 0 0 1">
        <inertial pos="0.0168606 3.93808e-10 0.02267" quat="0.949317 0 -0.314322 0" mass="0.0110931" diaginertia="5.59353e-06 3.96549e-06 1.88108e-06"/>
        <joint name="right_inner_knuckle_joint" pos="0 0 0" axis="0 1 0" range="0 0.8757" actuatorfrcrange="-1000 1000"/>
        <geom type="mesh" rgba="0.1 0.1 0.1 1" mesh="inner_knuckle_coarse"/>
        <body name="right_inner_finger" pos="0.034106 0 0.0458574">
          <inertial pos="0.00602756 0 0.00669926" quat="0.699065 0.106339 0.106339 0.699065" mass="0.00724255" diaginertia="1.70064e-06 1.58577e-06 3.69621e-07"/>
          <joint name="right_inner_finger_joint" pos="0 0 0" axis="0 1 0" range="0 0.8757" actuatorfrcrange="-1000 1000"/>
          <geom type="mesh" rgba="0.1 0.1 0.1 1" mesh="inner_finger_coarse"/>
        </body>
      </body>
      <body name="right_outer_knuckle" pos="-0.0306011 0 0.062792" quat="0 0 0 1">
        <inertial pos="0.029793 7.22554e-12 0.0164189" quat="0.704767 0.057475 0.057475 0.704767" mass="0.0341578" diaginertia="1.12323e-05 1.06532e-05 4.57606e-06"/>
        <joint name="right_outer_knuckle_joint" pos="0 0 0" axis="0 1 0" range="0 0.8757" actuatorfrcrange="-1000 1000"/>
        <geom type="mesh" rgba="0.1 0.1 0.1 1" mesh="outer_knuckle_coarse"/>
        <geom pos="0.0317096 0 -0.00160136" type="mesh" rgba="0.1 0.1 0.1 1" mesh="outer_finger_coarse"/>
      </body>
    </body>
  </worldbody>
</mujoco>
