<?xml version="1.0"?>
<robot name="phase4_franka_panda">
  <link name="panda_link0">
    <visual><geometry><mesh filename="/home/ziyaochen/torc_franka_lift3d_pipeline_v2/assets/franka/meshes/robosuite_panda_assets/meshes/link0.stl"/></geometry></visual>
    <collision><geometry><mesh filename="/home/ziyaochen/torc_franka_lift3d_pipeline_v2/assets/franka/meshes/robosuite_panda_assets/meshes/link0.stl"/></geometry></collision>
  </link>
  <link name="panda_link1">
    <visual><geometry><mesh filename="/home/ziyaochen/torc_franka_lift3d_pipeline_v2/assets/franka/meshes/robosuite_panda_assets/meshes/link1.stl"/></geometry></visual>
    <collision><geometry><mesh filename="/home/ziyaochen/torc_franka_lift3d_pipeline_v2/assets/franka/meshes/robosuite_panda_assets/meshes/link1.stl"/></geometry></collision>
  </link>
  <link name="panda_link2">
    <visual><geometry><mesh filename="/home/ziyaochen/torc_franka_lift3d_pipeline_v2/assets/franka/meshes/robosuite_panda_assets/meshes/link2.stl"/></geometry></visual>
    <collision><geometry><mesh filename="/home/ziyaochen/torc_franka_lift3d_pipeline_v2/assets/franka/meshes/robosuite_panda_assets/meshes/link2.stl"/></geometry></collision>
  </link>
  <link name="panda_link3">
    <visual><geometry><mesh filename="/home/ziyaochen/torc_franka_lift3d_pipeline_v2/assets/franka/meshes/robosuite_panda_assets/meshes/link3.stl"/></geometry></visual>
    <collision><geometry><mesh filename="/home/ziyaochen/torc_franka_lift3d_pipeline_v2/assets/franka/meshes/robosuite_panda_assets/meshes/link3.stl"/></geometry></collision>
  </link>
  <link name="panda_link4">
    <visual><geometry><mesh filename="/home/ziyaochen/torc_franka_lift3d_pipeline_v2/assets/franka/meshes/robosuite_panda_assets/meshes/link4.stl"/></geometry></visual>
    <collision><geometry><mesh filename="/home/ziyaochen/torc_franka_lift3d_pipeline_v2/assets/franka/meshes/robosuite_panda_assets/meshes/link4.stl"/></geometry></collision>
  </link>
  <link name="panda_link5">
    <visual><geometry><mesh filename="/home/ziyaochen/torc_franka_lift3d_pipeline_v2/assets/franka/meshes/robosuite_panda_assets/meshes/link5.stl"/></geometry></visual>
    <collision><geometry><mesh filename="/home/ziyaochen/torc_franka_lift3d_pipeline_v2/assets/franka/meshes/robosuite_panda_assets/meshes/link5.stl"/></geometry></collision>
  </link>
  <link name="panda_link6">
    <visual><geometry><mesh filename="/home/ziyaochen/torc_franka_lift3d_pipeline_v2/assets/franka/meshes/robosuite_panda_assets/meshes/link6.stl"/></geometry></visual>
    <collision><geometry><mesh filename="/home/ziyaochen/torc_franka_lift3d_pipeline_v2/assets/franka/meshes/robosuite_panda_assets/meshes/link6.stl"/></geometry></collision>
  </link>
  <link name="panda_link7">
    <visual><geometry><mesh filename="/home/ziyaochen/torc_franka_lift3d_pipeline_v2/assets/franka/meshes/robosuite_panda_assets/meshes/link7.stl"/></geometry></visual>
    <collision><geometry><mesh filename="/home/ziyaochen/torc_franka_lift3d_pipeline_v2/assets/franka/meshes/robosuite_panda_assets/meshes/link7.stl"/></geometry></collision>
  </link>
  <link name="panda_hand">
    <visual><geometry><mesh filename="/home/ziyaochen/torc_franka_lift3d_pipeline_v2/assets/franka/meshes/panda_gripper/hand_vis.stl"/></geometry></visual>
    <collision><geometry><mesh filename="/home/ziyaochen/torc_franka_lift3d_pipeline_v2/assets/franka/meshes/panda_gripper/hand.stl"/></geometry></collision>
  </link>
  <link name="panda_leftfinger">
    <visual><geometry><mesh filename="/home/ziyaochen/torc_franka_lift3d_pipeline_v2/assets/franka/meshes/panda_gripper/finger_vis.stl"/></geometry></visual>
    <collision><geometry><mesh filename="/home/ziyaochen/torc_franka_lift3d_pipeline_v2/assets/franka/meshes/panda_gripper/finger.stl"/></geometry></collision>
  </link>
  <link name="panda_rightfinger">
    <visual><geometry><mesh filename="/home/ziyaochen/torc_franka_lift3d_pipeline_v2/assets/franka/meshes/panda_gripper/finger_vis.stl"/></geometry></visual>
    <collision><geometry><mesh filename="/home/ziyaochen/torc_franka_lift3d_pipeline_v2/assets/franka/meshes/panda_gripper/finger.stl"/></geometry></collision>
  </link>
  <link name="panda_tcp"/>

  <joint name="robot0_joint1" type="revolute">
    <parent link="panda_link0"/><child link="panda_link1"/>
    <origin xyz="0 0 0.333" rpy="0 0 0"/><axis xyz="0 0 1"/>
    <limit lower="-2.8973" upper="2.8973" effort="80" velocity="2.175"/>
  </joint>
  <joint name="robot0_joint2" type="revolute">
    <parent link="panda_link1"/><child link="panda_link2"/>
    <origin xyz="0 0 0" rpy="-1.57079632679 0 0"/><axis xyz="0 0 1"/>
    <limit lower="-1.7628" upper="1.7628" effort="80" velocity="2.175"/>
  </joint>
  <joint name="robot0_joint3" type="revolute">
    <parent link="panda_link2"/><child link="panda_link3"/>
    <origin xyz="0 -0.316 0" rpy="1.57079632679 0 0"/><axis xyz="0 0 1"/>
    <limit lower="-2.8973" upper="2.8973" effort="80" velocity="2.175"/>
  </joint>
  <joint name="robot0_joint4" type="revolute">
    <parent link="panda_link3"/><child link="panda_link4"/>
    <origin xyz="0.0825 0 0" rpy="1.57079632679 0 0"/><axis xyz="0 0 1"/>
    <limit lower="-3.0718" upper="-0.0698" effort="80" velocity="2.175"/>
  </joint>
  <joint name="robot0_joint5" type="revolute">
    <parent link="panda_link4"/><child link="panda_link5"/>
    <origin xyz="-0.0825 0.384 0" rpy="-1.57079632679 0 0"/><axis xyz="0 0 1"/>
    <limit lower="-2.8973" upper="2.8973" effort="12" velocity="2.61"/>
  </joint>
  <joint name="robot0_joint6" type="revolute">
    <parent link="panda_link5"/><child link="panda_link6"/>
    <origin xyz="0 0 0" rpy="1.57079632679 0 0"/><axis xyz="0 0 1"/>
    <limit lower="-0.0175" upper="3.7525" effort="12" velocity="2.61"/>
  </joint>
  <joint name="robot0_joint7" type="revolute">
    <parent link="panda_link6"/><child link="panda_link7"/>
    <origin xyz="0.088 0 0" rpy="1.57079632679 0 0"/><axis xyz="0 0 1"/>
    <limit lower="-2.8973" upper="2.8973" effort="12" velocity="2.61"/>
  </joint>
  <joint name="panda_hand_fixed" type="fixed">
    <parent link="panda_link7"/><child link="panda_hand"/>
    <origin xyz="0 0 0.1065" rpy="0 0 -0.78539816339"/>
  </joint>
  <joint name="gripper0_right_finger_joint1" type="prismatic">
    <parent link="panda_hand"/><child link="panda_leftfinger"/>
    <origin xyz="0 0 0.0524" rpy="0 0 1.57079632679"/><axis xyz="0 1 0"/>
    <limit lower="0.0" upper="0.04" effort="20" velocity="0.2"/>
  </joint>
  <joint name="gripper0_right_finger_joint2" type="prismatic">
    <parent link="panda_hand"/><child link="panda_rightfinger"/>
    <origin xyz="0 0 0.0524" rpy="0 0 1.57079632679"/><axis xyz="0 1 0"/>
    <limit lower="-0.04" upper="0.0" effort="20" velocity="0.2"/>
  </joint>
  <joint name="panda_tcp_fixed" type="fixed">
    <parent link="panda_hand"/><child link="panda_tcp"/>
    <origin xyz="0 0 0.097" rpy="0 0 -1.57079632679"/>
  </joint>
</robot>
